# 第02节：异常处理

### 一、抛出异常

throws的作用是声明抛出异常，在方法声明的位置上使用throws关键字向上抛出异常。例如下面程序演示了一般性异常，编译无法通过，需要对异常进行处理

``` java
import java.io.FileInputStream;

public class ExceptionTest{

    public static void main(String[] args){
        //这句代码的意思是创建文件输入流，读取文件，遇到不认识的类可以查看API
        FileInputStream fis = new FileInputStream("d:/xiaozhou.txt");

    }
}
```

可以使用throws将异常抛出

``` java
import java.io.*;

public class ExceptionTest {

    public static void main(String[] args) throws FileNotFoundException{
        //这句代码的意思是创建文件输入流，读取文件
        FileInputStream fis = new FileInputStream("d:/xiaozhou.txt");

    }
}
```

jvm是怎么知道这个地方容易出现问题呢？来看下FileInputStream的源码

``` java
public FileInputStream(String name) throws FileNotFoundException {
    this(name != null ? new File(name) : null);
}
```

源码里面在构造方法上抛出了FileNotFoundException，所以jvm知道。

其实使用throws抛出异常并不是真正的去处理异常，而是抛给其调用者去处理，比如你在工作中遇到问题了，交给了你的领导去解决，领导如果也不想解决就交给他的领导去解决。在上面程序里面，我们抛出了异常，最后是交给了jvm解决，jvm的解决方式就是将错误信息打印至控制台，然后关闭程序。
下面示例展示了将异常抛出的情况

``` java
import java.io.*;

public class ExceptionTest04{

    public static void main(String[] args) throws FileNotFoundException{

        //抛给调用者，如果都不进行处理的话，最终抛给了main方法
        m1();
    }

    public static void m1() throws FileNotFoundException{
        m2();
    }


    public static void m2() throws FileNotFoundException{
        m3();
    }

    //向上抛出异常
    public static void m3() throws FileNotFoundException{
        FileInputStream fis = new FileInputStream("c:/xiaozhou.txt"); 
    }

}
```

这里不是说使用throws是不好，使用throws主要意图是暴露问题，如何解决让调用者去决定

### 二、捕获异常

可以使用try…catch…处理异常，例如之前的程序可以使用try…catch…处理

``` java
package com.xiaozhou.exception;

import java.io.FileInputStream;
import java.io.FileNotFoundException;

public class ExceptionTest02 {

    public static void main(String[] args) {
         try {
            FileInputStream fis = new FileInputStream("d:/xiaozhou.txt");
            //捕捉FileNotFoundException异常
        } catch (FileNotFoundException e) {//jvm会创建FileNotFoundException的对象，然后将e指向这个对象
            //如果try里面的代码没有报错，则不会执行catch里面的代码
            e.printStackTrace();//打印出异常信息
            String msg = e.getMessage();
            System.out.println(msg);
        }
        System.out.println("xiaozhou.com");//catch后面的语句会正常执行
    }

}
```

可以捕捉多个异常，但是catch里面必须从小类型异常到大类型异常进行捕捉，先捕捉子后捕捉父，最多执行一个catch语句块里面的内容。

``` java
package com.xiaozhou.exception;

import java.io.FileInputStream;
import java.io.FileNotFoundException;
import java.io.IOException;

public class ExceptionTest02 {

    public static void main(String[] args) {
         try {
            FileInputStream fis = new FileInputStream("d:/xiaozhou.txt");
            fis.read();
        } catch (FileNotFoundException e) {//捕捉FileNotFoundException异常
            e.printStackTrace();
        } catch (IOException e) {//捕捉IOException异常
            e.printStackTrace();
        } catch (Exception e) {//捕捉Exception异常
            e.printStackTrace();
        } 
    }

}
```

jdk7新特性
jdk7新特性，可以将多个捕捉的异常放到一个catch里面

``` java
package com.xiaozhou.exception;

import java.io.FileInputStream;
import java.io.FileNotFoundException;

public class ExceptionTest03 {

    public static void main(String[] args) {

        try {
            System.out.println(1024 / 0);
            FileInputStream fis = new FileInputStream("d:/xiaozhou.txt");
            //jdk7新特性，可以将多个异常放到一个catch里面
        } catch (FileNotFoundException | ArithmeticException e) {
            e.printStackTrace();
        } /*catch (ArithmeticException e){
            e.printStackTrace();
        }*/
    }

}
```

### 三、finally关键字

finally的特点

被finally控制的语句体一定会执行，除非在执行finally语句体之前JVM退出(比如System.exit(0))，一般用于关闭资源

finally如何使用？

finally语句块可以直接和try语句块联用：try….finally…（这种用的比较少）
也可以这样使用：try…catch….finally

``` java
package com.monkey1024.exception;

public class FinallyTest01 {

    public static void main(String[] args) {

        try {
            System.out.println(1024 / 0);
        } catch (ArithmeticException e) {
            e.printStackTrace();
        } finally{
            System.out.println("finally中的内容");
        }
    }

}
```

即使在方法里面执行了return，finally中的代码也会执行

``` java
package com.monkey1024.exception;

public class FinallyTest02 {
public static void main(String[] args){

        int i = m1();
        System.out.println(i); 

    }

    public static int m1(){

        int i = 10;
        try{
            return i;
        }finally{
            System.out.println("finally中的语句");
        }

    }

}
```

只有当finally语句执行之前，JVM退出了，finally才不会执行：

``` java
package com.monkey1024.exception;

public class FinallyTest02 {
public static void main(String[] args){

        int i = m1();
        System.out.println(i); 

    }

    public static int m1(){

       try {
           int i = 1024;//try里面的变量在外部是无法被访问的
           System.exit(0);//让jvm退出，所以finally中的语句不会执行
           return i;
        } catch (Exception e) {
            e.printStackTrace();
        } finally {
            System.out.println("finally中的语句");
        }
       return 10;
       // System.out.println(i);无法访问i，因为i是在try中声明的

    }

}
```